<mujoco model="partnet_190cb7264781df604da5feafe6f1c8fc">
    <compiler angle="radian" />
    <size njmax="500" nconmax="100" />
    <asset>
        <mesh name="convex-65" file="convex-65.stl" />
        <mesh name="convex-67" file="convex-67.stl" />
        <mesh name="convex-69" file="convex-69.stl" />
        <mesh name="convex-68" file="convex-68.stl" />
        <mesh name="convex-59" file="convex-59.stl" />
        <mesh name="convex-61" file="convex-61.stl" />
        <mesh name="convex-63" file="convex-63.stl" />
        <mesh name="convex-62" file="convex-62.stl" />
        <mesh name="convex-29" file="convex-29.stl" />
        <mesh name="convex-37" file="convex-37.stl" />
        <mesh name="convex-33" file="convex-33.stl" />
        <mesh name="convex-35" file="convex-35.stl" />
        <mesh name="convex-28" file="convex-28.stl" />
        <mesh name="convex-34" file="convex-34.stl" />
        <mesh name="convex-32" file="convex-32.stl" />
        <mesh name="convex-31" file="convex-31.stl" />
        <mesh name="convex-39" file="convex-39.stl" />
        <mesh name="convex-40" file="convex-40.stl" />
        <mesh name="convex-41" file="convex-41.stl" />
        <mesh name="convex-45" file="convex-45.stl" />
        <mesh name="convex-53" file="convex-53.stl" />
        <mesh name="convex-44" file="convex-44.stl" />
        <mesh name="convex-49" file="convex-49.stl" />
        <mesh name="convex-51" file="convex-51.stl" />
        <mesh name="convex-50" file="convex-50.stl" />
        <mesh name="convex-48" file="convex-48.stl" />
        <mesh name="convex-47" file="convex-47.stl" />
        <mesh name="convex-55" file="convex-55.stl" />
        <mesh name="convex-56" file="convex-56.stl" />
        <mesh name="convex-57" file="convex-57.stl" />
        <mesh name="convex-25" file="convex-25.stl" />
        <mesh name="convex-70" file="convex-70.stl" />
        <mesh name="convex-12" file="convex-12.stl" />
        <mesh name="convex-11" file="convex-11.stl" />
        <mesh name="convex-16" file="convex-16.stl" />
        <mesh name="convex-15" file="convex-15.stl" />
        <mesh name="convex-18" file="convex-18.stl" />
        <mesh name="convex-19" file="convex-19.stl" />
        <mesh name="convex-24" file="convex-24.stl" />
        <mesh name="convex-7" file="convex-7.stl" />
        <mesh name="convex-8" file="convex-8.stl" />
        <mesh name="convex-4" file="convex-4.stl" />
        <mesh name="convex-9" file="convex-9.stl" />
        <mesh name="convex-6" file="convex-6.stl" />
        <mesh name="convex-5" file="convex-5.stl" />
        <mesh name="convex-3" file="convex-3.stl" />
        <mesh name="convex-23" file="convex-23.stl" />
        <mesh name="convex-22" file="convex-22.stl" />
        <mesh name="convex-13" file="convex-13.stl" />
        <mesh name="convex-17" file="convex-17.stl" />
        <mesh name="convex-21" file="convex-21.stl" />
        <mesh name="convex-20" file="convex-20.stl" />
    </asset>
    <worldbody>
        <geom quat="0.5 0.5 -0.5 -0.5" type="mesh" mesh="convex-25" />
        <geom quat="0.5 0.5 -0.5 -0.5" type="mesh" mesh="convex-70" />
        <geom quat="0.5 0.5 -0.5 -0.5" type="mesh" mesh="convex-12" />
        <geom quat="0.5 0.5 -0.5 -0.5" type="mesh" mesh="convex-11" />
        <geom quat="0.5 0.5 -0.5 -0.5" type="mesh" mesh="convex-16" />
        <geom quat="0.5 0.5 -0.5 -0.5" type="mesh" mesh="convex-15" />
        <geom quat="0.5 0.5 -0.5 -0.5" type="mesh" mesh="convex-18" />
        <geom quat="0.5 0.5 -0.5 -0.5" type="mesh" mesh="convex-19" />
        <geom quat="0.5 0.5 -0.5 -0.5" type="mesh" mesh="convex-24" />
        <geom quat="0.5 0.5 -0.5 -0.5" type="mesh" mesh="convex-7" />
        <geom quat="0.5 0.5 -0.5 -0.5" type="mesh" mesh="convex-8" />
        <geom quat="0.5 0.5 -0.5 -0.5" type="mesh" mesh="convex-4" />
        <geom quat="0.5 0.5 -0.5 -0.5" type="mesh" mesh="convex-9" />
        <geom quat="0.5 0.5 -0.5 -0.5" type="mesh" mesh="convex-6" />
        <geom quat="0.5 0.5 -0.5 -0.5" type="mesh" mesh="convex-5" />
        <geom quat="0.5 0.5 -0.5 -0.5" type="mesh" mesh="convex-3" />
        <geom quat="0.5 0.5 -0.5 -0.5" type="mesh" mesh="convex-23" />
        <geom quat="0.5 0.5 -0.5 -0.5" type="mesh" mesh="convex-22" />
        <geom quat="0.5 0.5 -0.5 -0.5" type="mesh" mesh="convex-13" />
        <geom quat="0.5 0.5 -0.5 -0.5" type="mesh" mesh="convex-17" />
        <geom quat="0.5 0.5 -0.5 -0.5" type="mesh" mesh="convex-21" />
        <geom quat="0.5 0.5 -0.5 -0.5" type="mesh" mesh="convex-20" />
        <body name="link_0" pos="-0.411765 -0.668161 -0.500258" quat="0.5 0.5 -0.5 -0.5">
            <inertial pos="-0.32929 0.0902366 -0.513415" quat="0.705843 -0.00566432 -0.00625225 0.708318" mass="21.4575" diaginertia="2.03334 1.16583 0.87382" />
            <joint name="joint_0" pos="0 0 0" axis="0 1 0" limited="true" range="0 1.5708" />
            <geom pos="-0.668161 0.500258 -0.411765" type="mesh" mesh="convex-65" />
            <geom pos="-0.668161 0.500258 -0.411765" type="mesh" mesh="convex-67" />
            <geom pos="-0.668161 0.500258 -0.411765" type="mesh" mesh="convex-69" />
            <geom pos="-0.668161 0.500258 -0.411765" type="mesh" mesh="convex-68" />
        </body>
        <body name="link_1" pos="-0.409826 0.681307 -0.500258" quat="0.5 0.5 -0.5 -0.5">
            <inertial pos="0.331951 0.0902366 -0.511476" quat="0.70831 0.00620442 0.00561664 0.705852" mass="21.4575" diaginertia="2.03311 1.16583 0.873593" />
            <joint name="joint_1" pos="0 0 0" axis="0 -1 0" limited="true" range="0 1.5708" />
            <geom pos="0.681307 0.500258 -0.409826" type="mesh" mesh="convex-59" />
            <geom pos="0.681307 0.500258 -0.409826" type="mesh" mesh="convex-61" />
            <geom pos="0.681307 0.500258 -0.409826" type="mesh" mesh="convex-63" />
            <geom pos="0.681307 0.500258 -0.409826" type="mesh" mesh="convex-62" />
        </body>
        <body name="link_2" pos="0.416492 -0.321637 0.407848" quat="0.5 0.5 -0.5 -0.5">
            <inertial pos="0.0190409 -0.573552 0.837077" quat="0.504432 0.495578 -0.495796 0.504121" mass="15.4918" diaginertia="1.71561 1.14569 0.64144" />
            <joint name="joint_2" pos="0 0 0" axis="0 0 1" type="slide" limited="true" range="0 0.64" />
            <geom pos="-0.321637 -0.407848 0.416492" type="mesh" mesh="convex-29" />
            <geom pos="-0.321637 -0.407848 0.416492" type="mesh" mesh="convex-37" />
            <geom pos="-0.321637 -0.407848 0.416492" type="mesh" mesh="convex-33" />
            <geom pos="-0.321637 -0.407848 0.416492" type="mesh" mesh="convex-35" />
            <geom pos="-0.321637 -0.407848 0.416492" type="mesh" mesh="convex-28" />
            <geom pos="-0.321637 -0.407848 0.416492" type="mesh" mesh="convex-34" />
            <geom pos="-0.321637 -0.407848 0.416492" type="mesh" mesh="convex-32" />
            <geom pos="-0.321637 -0.407848 0.416492" type="mesh" mesh="convex-31" />
            <geom pos="-0.321637 -0.407848 0.416492" type="mesh" mesh="convex-39" />
            <geom pos="-0.321637 -0.407848 0.416492" type="mesh" mesh="convex-40" />
            <geom pos="-0.321637 -0.407848 0.416492" type="mesh" mesh="convex-41" />
        </body>
        <body name="link_3" pos="0.416492 0.364208 0.405967" quat="0.5 0.5 -0.5 -0.5">
            <inertial pos="0.011502 -0.57165 0.837084" quat="0.504433 0.495578 -0.495783 0.504131" mass="15.49" diaginertia="1.71542 1.14556 0.641346" />
            <joint name="joint_3" pos="0 0 0" axis="0 0 1" type="slide" limited="true" range="0 0.64" />
            <geom pos="0.364208 -0.405967 0.416492" type="mesh" mesh="convex-45" />
            <geom pos="0.364208 -0.405967 0.416492" type="mesh" mesh="convex-53" />
            <geom pos="0.364208 -0.405967 0.416492" type="mesh" mesh="convex-44" />
            <geom pos="0.364208 -0.405967 0.416492" type="mesh" mesh="convex-49" />
            <geom pos="0.364208 -0.405967 0.416492" type="mesh" mesh="convex-51" />
            <geom pos="0.364208 -0.405967 0.416492" type="mesh" mesh="convex-50" />
            <geom pos="0.364208 -0.405967 0.416492" type="mesh" mesh="convex-48" />
            <geom pos="0.364208 -0.405967 0.416492" type="mesh" mesh="convex-47" />
            <geom pos="0.364208 -0.405967 0.416492" type="mesh" mesh="convex-55" />
            <geom pos="0.364208 -0.405967 0.416492" type="mesh" mesh="convex-56" />
            <geom pos="0.364208 -0.405967 0.416492" type="mesh" mesh="convex-57" />
        </body>
    </worldbody>
</mujoco>
