<?xml version="1.0" ?>
<robot name="partnet_95bc6fb98624ea3229d75ea275a1cb4e">
	<link name="base"/>
	<link name="link_0">
		<visual name="door_frame-16">
			<origin xyz="-0.7790369987487793 0.26448509051760233 -0.39998197661063867"/>
			<geometry>
				<mesh filename="textured_objs/original-22.stl"/>
			</geometry>
		</visual>
		<visual name="door_frame-16">
			<origin xyz="-0.7790369987487793 0.26448509051760233 -0.39998197661063867"/>
			<geometry>
				<mesh filename="textured_objs/original-18.stl"/>
			</geometry>
		</visual>
		<visual name="door_frame-16">
			<origin xyz="-0.7790369987487793 0.26448509051760233 -0.39998197661063867"/>
			<geometry>
				<mesh filename="textured_objs/original-20.stl"/>
			</geometry>
		</visual>
		<visual name="door_frame-16">
			<origin xyz="-0.7790369987487793 0.26448509051760233 -0.39998197661063867"/>
			<geometry>
				<mesh filename="textured_objs/original-21.stl"/>
			</geometry>
		</visual>
		<visual name="glass-17">
			<origin xyz="-0.7790369987487793 0.26448509051760233 -0.39998197661063867"/>
			<geometry>
				<mesh filename="textured_objs/original-23.stl"/>
			</geometry>
		</visual>
		<collision>
			<origin xyz="-0.7790369987487793 0.26448509051760233 -0.39998197661063867"/>
			<geometry>
				<mesh filename="textured_objs/original-22.stl"/>
			</geometry>
		</collision>
		<collision>
			<origin xyz="-0.7790369987487793 0.26448509051760233 -0.39998197661063867"/>
			<geometry>
				<mesh filename="textured_objs/original-18.stl"/>
			</geometry>
		</collision>
		<collision>
			<origin xyz="-0.7790369987487793 0.26448509051760233 -0.39998197661063867"/>
			<geometry>
				<mesh filename="textured_objs/original-20.stl"/>
			</geometry>
		</collision>
		<collision>
			<origin xyz="-0.7790369987487793 0.26448509051760233 -0.39998197661063867"/>
			<geometry>
				<mesh filename="textured_objs/original-21.stl"/>
			</geometry>
		</collision>
		<collision>
			<origin xyz="-0.7790369987487793 0.26448509051760233 -0.39998197661063867"/>
			<geometry>
				<mesh filename="textured_objs/original-23.stl"/>
			</geometry>
		</collision>
	</link>
	<joint name="joint_0" type="revolute">
		<origin xyz="0.7790369987487793 -0.26448509051760233 0.39998197661063867"/>
		<axis xyz="1 0 0"/>
		<child link="link_0"/>
		<parent link="link_3"/>
		<limit lower="0.0" upper="1.5707963267948966"/>
	</joint>
	<link name="link_1">
		<visual name="control_button-9">
			<origin xyz="0.3010604613555175 0.40193595354091266 -0.4624199867248535"/>
			<geometry>
				<mesh filename="textured_objs/original-10.stl"/>
			</geometry>
		</visual>
		<collision>
			<origin xyz="0.3010604613555175 0.40193595354091266 -0.4624199867248535"/>
			<geometry>
				<mesh filename="textured_objs/original-10.stl"/>
			</geometry>
		</collision>
	</link>
	<joint name="joint_1" type="continuous">
		<origin xyz="-0.3010604613555175 -0.40193595354091266 0.4624199867248535"/>
		<axis xyz="0 0 1"/>
		<child link="link_1"/>
		<parent link="link_3"/>
	</joint>
	<link name="link_2">
		<visual name="control_button-10">
			<origin xyz="-0.2990942989371162 0.40305538184674927 -0.4624199867248535"/>
			<geometry>
				<mesh filename="textured_objs/original-11.stl"/>
			</geometry>
		</visual>
		<collision>
			<origin xyz="-0.2990942989371162 0.40305538184674927 -0.4624199867248535"/>
			<geometry>
				<mesh filename="textured_objs/original-11.stl"/>
			</geometry>
		</collision>
	</link>
	<joint name="joint_2" type="continuous">
		<origin xyz="0.2990942989371162 -0.40305538184674927 0.4624199867248535"/>
		<axis xyz="0 0 1"/>
		<child link="link_2"/>
		<parent link="link_3"/>
	</joint>
	<link name="link_3">
		<visual name="frame-2">
			<origin xyz="0 0 0"/>
			<geometry>
				<mesh filename="textured_objs/original-16.stl"/>
			</geometry>
		</visual>
		<visual name="frame-2">
			<origin xyz="0 0 0"/>
			<geometry>
				<mesh filename="textured_objs/original-1.stl"/>
			</geometry>
		</visual>
		<visual name="control_button-5">
			<origin xyz="0 0 0"/>
			<geometry>
				<mesh filename="textured_objs/original-12.stl"/>
			</geometry>
		</visual>
		<visual name="control_button-6">
			<origin xyz="0 0 0"/>
			<geometry>
				<mesh filename="textured_objs/original-13.stl"/>
			</geometry>
		</visual>
		<visual name="control_button-7">
			<origin xyz="0 0 0"/>
			<geometry>
				<mesh filename="textured_objs/original-14.stl"/>
			</geometry>
		</visual>
		<visual name="control_button-8">
			<origin xyz="0 0 0"/>
			<geometry>
				<mesh filename="textured_objs/original-15.stl"/>
			</geometry>
		</visual>
		<visual name="display_panel-11">
			<origin xyz="0 0 0"/>
			<geometry>
				<mesh filename="textured_objs/original-8.stl"/>
			</geometry>
		</visual>
		<visual name="indicator-18">
			<origin xyz="0 0 0"/>
			<geometry>
				<mesh filename="textured_objs/original-7.stl"/>
			</geometry>
		</visual>
		<visual name="indicator-19">
			<origin xyz="0 0 0"/>
			<geometry>
				<mesh filename="textured_objs/original-6.stl"/>
			</geometry>
		</visual>
		<visual name="indicator-20">
			<origin xyz="0 0 0"/>
			<geometry>
				<mesh filename="textured_objs/original-5.stl"/>
			</geometry>
		</visual>
		<visual name="indicator-21">
			<origin xyz="0 0 0"/>
			<geometry>
				<mesh filename="textured_objs/original-4.stl"/>
			</geometry>
		</visual>
		<collision>
			<origin xyz="0 0 0"/>
			<geometry>
				<mesh filename="textured_objs/original-16.stl"/>
			</geometry>
		</collision>
		<collision>
			<origin xyz="0 0 0"/>
			<geometry>
				<mesh filename="textured_objs/original-1.stl"/>
			</geometry>
		</collision>
		<collision>
			<origin xyz="0 0 0"/>
			<geometry>
				<mesh filename="textured_objs/original-12.stl"/>
			</geometry>
		</collision>
		<collision>
			<origin xyz="0 0 0"/>
			<geometry>
				<mesh filename="textured_objs/original-13.stl"/>
			</geometry>
		</collision>
		<collision>
			<origin xyz="0 0 0"/>
			<geometry>
				<mesh filename="textured_objs/original-14.stl"/>
			</geometry>
		</collision>
		<collision>
			<origin xyz="0 0 0"/>
			<geometry>
				<mesh filename="textured_objs/original-15.stl"/>
			</geometry>
		</collision>
		<collision>
			<origin xyz="0 0 0"/>
			<geometry>
				<mesh filename="textured_objs/original-8.stl"/>
			</geometry>
		</collision>
		<collision>
			<origin xyz="0 0 0"/>
			<geometry>
				<mesh filename="textured_objs/original-7.stl"/>
			</geometry>
		</collision>
		<collision>
			<origin xyz="0 0 0"/>
			<geometry>
				<mesh filename="textured_objs/original-6.stl"/>
			</geometry>
		</collision>
		<collision>
			<origin xyz="0 0 0"/>
			<geometry>
				<mesh filename="textured_objs/original-5.stl"/>
			</geometry>
		</collision>
		<collision>
			<origin xyz="0 0 0"/>
			<geometry>
				<mesh filename="textured_objs/original-4.stl"/>
			</geometry>
		</collision>
	</link>
	<joint name="joint_3" type="fixed">
		<origin rpy="1.570796326794897 0 -1.570796326794897" xyz="0 0 0"/>
		<child link="link_3"/>
		<parent link="base"/>
	</joint>
</robot>
