<mujoco model="partnet_891f65c773939191c834958aed613724">
    <compiler angle="radian" />
    <size njmax="500" nconmax="100" />
    <asset>
        <mesh name="new-6" file="new-6.stl" scale="0.3 0.3 0.3" />
        <mesh name="new-5" file="new-5.stl" scale="0.3 0.3 0.3" />
        <mesh name="original-3" file="original-3.stl" scale="0.3 0.3 0.3" />
        <mesh name="original-4" file="original-4.stl" scale="0.3 0.3 0.3" />
        <mesh name="original-41" file="original-41.stl" scale="0.3 0.3 0.3" />
        <mesh name="original-36" file="original-36.stl" scale="0.3 0.3 0.3" />
        <mesh name="original-35" file="original-35.stl" scale="0.3 0.3 0.3" />
        <mesh name="original-19" file="original-19.stl" scale="0.3 0.3 0.3" />
        <mesh name="original-42" file="original-42.stl" scale="0.3 0.3 0.3" />
        <mesh name="original-34" file="original-34.stl" scale="0.3 0.3 0.3" />
        <mesh name="original-31" file="original-31.stl" scale="0.3 0.3 0.3" />
        <mesh name="original-18" file="original-18.stl" scale="0.3 0.3 0.3" />
        <mesh name="original-17" file="original-17.stl" scale="0.3 0.3 0.3" />
        <mesh name="original-33" file="original-33.stl" scale="0.3 0.3 0.3" />
        <mesh name="original-32" file="original-32.stl" scale="0.3 0.3 0.3" />
        <mesh name="original-16" file="original-16.stl" scale="0.3 0.3 0.3" />
        <mesh name="original-15" file="original-15.stl" scale="0.3 0.3 0.3" />
        <mesh name="original-30" file="original-30.stl" scale="0.3 0.3 0.3" />
        <mesh name="original-14" file="original-14.stl" scale="0.3 0.3 0.3" />
        <mesh name="original-29" file="original-29.stl" scale="0.3 0.3 0.3" />
        <mesh name="original-40" file="original-40.stl" scale="0.3 0.3 0.3" />
        <mesh name="original-13" file="original-13.stl" scale="0.3 0.3 0.3" />
        <mesh name="original-39" file="original-39.stl" scale="0.3 0.3 0.3" />
        <mesh name="original-22" file="original-22.stl" scale="0.3 0.3 0.3" />
        <mesh name="original-20" file="original-20.stl" scale="0.3 0.3 0.3" />
        <mesh name="original-38" file="original-38.stl" scale="0.3 0.3 0.3" />
        <mesh name="original-23" file="original-23.stl" scale="0.3 0.3 0.3" />
        <mesh name="original-37" file="original-37.stl" scale="0.3 0.3 0.3" />
        <mesh name="original-48" file="original-48.stl" scale="0.3 0.3 0.3" />
        <mesh name="original-21" file="original-21.stl" scale="0.3 0.3 0.3" />
        <mesh name="original-46" file="original-46.stl" scale="0.3 0.3 0.3" />
        <mesh name="original-27" file="original-27.stl" scale="0.3 0.3 0.3" />
        <mesh name="original-28" file="original-28.stl" scale="0.3 0.3 0.3" />
        <mesh name="original-45" file="original-45.stl" scale="0.3 0.3 0.3" />
        <mesh name="original-47" file="original-47.stl" scale="0.3 0.3 0.3" />
        <mesh name="original-25" file="original-25.stl" scale="0.3 0.3 0.3" />
        <mesh name="original-44" file="original-44.stl" scale="0.3 0.3 0.3" />
        <mesh name="original-24" file="original-24.stl" scale="0.3 0.3 0.3" />
        <mesh name="original-43" file="original-43.stl" scale="0.3 0.3 0.3" />
        <mesh name="original-26" file="original-26.stl" scale="0.3 0.3 0.3" />
        <mesh name="original-10" file="original-10.stl" scale="0.3 0.3 0.3" />
        <mesh name="original-12" file="original-12.stl" scale="0.3 0.3 0.3" />
        <mesh name="new-4" file="new-4.stl" scale="0.3 0.3 0.3" />
        <mesh name="original-49" file="original-49.stl" scale="0.3 0.3 0.3" />
        <mesh name="original-51" file="original-51.stl" scale="0.3 0.3 0.3" />
        <mesh name="original-1" file="original-1.stl" scale="0.3 0.3 0.3" />
        <mesh name="original-50" file="original-50.stl" scale="0.3 0.3 0.3" />
        <mesh name="new-3" file="new-3.stl" scale="0.3 0.3 0.3" />
        <mesh name="new-2" file="new-2.stl" scale="0.3 0.3 0.3" />
        <mesh name="new-1" file="new-1.stl" scale="0.3 0.3 0.3" />
        <mesh name="new-0" file="new-0.stl" scale="0.3 0.3 0.3" />
    </asset>
    <worldbody>
    <body>
        <body name="object">
        <geom quat="0.5 0.5 -0.5 -0.5" type="mesh" group="0" mesh="original-12" conaffinity="0" contype="0" />
        <geom quat="0.5 0.5 -0.5 -0.5" type="mesh" group="0" mesh="new-4" conaffinity="0" contype="0" />
        <geom quat="0.5 0.5 -0.5 -0.5" type="mesh" group="0" mesh="original-49" conaffinity="0" contype="0" />
        <geom quat="0.5 0.5 -0.5 -0.5" type="mesh" group="0" mesh="original-51" conaffinity="0" contype="0" />
        <geom quat="0.5 0.5 -0.5 -0.5" type="mesh" group="0" mesh="original-1" conaffinity="0" contype="0" />
        <geom quat="0.5 0.5 -0.5 -0.5" type="mesh" group="0" mesh="original-50" conaffinity="0" contype="0" />
        <geom quat="0.5 0.5 -0.5 -0.5" type="mesh" group="0" mesh="new-3" conaffinity="0" contype="0" />
        <geom quat="0.5 0.5 -0.5 -0.5" type="mesh" group="0" mesh="new-2" conaffinity="0" contype="0" />
        <geom quat="0.5 0.5 -0.5 -0.5" type="mesh" group="0" mesh="new-1" conaffinity="0" contype="0" />
        <geom quat="0.5 0.5 -0.5 -0.5" type="mesh" group="0" mesh="new-0" conaffinity="0" contype="0" />
        <body name="link_0" pos="-0.1077654 0.1856355 0.0" quat="0.5 0.5 -0.5 -0.5">
            <inertial pos="0.1244487 0.00499332 0.0896772" quat="0.00349468 0.499467 -0.00703786 0.866297" mass="72.4061" diaginertia="9.0744 5.85664 3.30306" />
            <joint name="joint_0" pos="0.0 0.0 0.0" axis="0 -1 0" limited="true" range="-0.523599 1.39626" />
            
            <geom name="panel" pos="0.1856355 0.0 -0.1077654" type="mesh" group="0" mesh="new-6" />
            <geom pos="0.1856355 0.0 -0.1077654" type="mesh" group="0" mesh="new-5" />
            <geom pos="0.1856355 0.0 -0.1077654" type="mesh" group="0" mesh="original-3" />
            <geom pos="0.1856355 0.0 -0.1077654" type="mesh" group="0" mesh="original-4" />
        </body>
        <body name="link_1" pos="-0.1367352 -0.16256459999999998 -0.06872099999999999" quat="0.5 0.5 -0.5 -0.5">
            <inertial pos="0.015758039999999997 0.02348802 0.0014827559999999998" quat="0.416789 0.571373 -0.416729 0.571101" mass="0.0153622" diaginertia="5.42181e-06 2.78238e-06 2.76854e-06" />
            <joint name="joint_1" pos="0.0 0.0 0.0" axis="0 0 -1" type="slide" limited="true" range="0.0 0.0012" />
            <geom pos="-0.16256459999999998 0.06872099999999999 -0.1367352" type="mesh" group="0" mesh="original-41" />
            <geom pos="-0.16256459999999998 0.06872099999999999 -0.1367352" type="mesh" group="0" mesh="original-36" />
        </body>
        <body name="link_2" pos="-0.1367352 -0.16256459999999998 -0.06872099999999999" quat="0.5 0.5 -0.5 -0.5">
            <inertial pos="-0.00565305 0.023483909999999997 0.0014769989999999999" quat="0.523586 0.475286 -0.523487 0.475312" mass="0.0152598" diaginertia="5.40253e-06 2.76766e-06 2.76238e-06" />
            <joint name="joint_2" pos="0.0 0.0 0.0" axis="0 0 -1" type="slide" limited="true" range="0.0 0.0012" />
            <geom pos="-0.16256459999999998 0.06872099999999999 -0.1367352" type="mesh" group="0" mesh="original-35" />
            <geom pos="-0.16256459999999998 0.06872099999999999 -0.1367352" type="mesh" group="0" mesh="original-19" />
        </body>
        <body name="link_3" pos="-0.1367352 -0.16256459999999998 -0.06872099999999999" quat="0.5 0.5 -0.5 -0.5">
            <inertial pos="-0.02708955 0.023480309999999997 0.001485852" quat="0.511133 0.489369 -0.510207 0.488824" mass="0.0154119" diaginertia="5.43794e-06 2.79688e-06 2.77117e-06" />
            <joint name="joint_3" pos="0.0 0.0 0.0" axis="0 0 -1" type="slide" limited="true" range="0.0 0.0012" />
            <geom pos="-0.16256459999999998 0.06872099999999999 -0.1367352" type="mesh" group="0" mesh="original-42" />
            <geom pos="-0.16256459999999998 0.06872099999999999 -0.1367352" type="mesh" group="0" mesh="original-34" />
        </body>
        <body name="link_4" pos="-0.1367352 -0.16256459999999998 -0.06872099999999999" quat="0.5 0.5 -0.5 -0.5">
            <inertial pos="0.01576515 0.0434799 0.001475853" quat="0.433322 0.558723 -0.433633 0.55859" mass="0.015244" diaginertia="5.40095e-06 2.76746e-06 2.76057e-06" />
            <joint name="joint_4" pos="0.0 0.0 0.0" axis="0 0 -1" type="slide" limited="true" range="0.0 0.0012" />
            <geom pos="-0.16256459999999998 0.06872099999999999 -0.1367352" type="mesh" group="0" mesh="original-31" />
            <geom pos="-0.16256459999999998 0.06872099999999999 -0.1367352" type="mesh" group="0" mesh="original-18" />
        </body>
        <body name="link_5" pos="-0.1367352 -0.16256459999999998 -0.06872099999999999" quat="0.5 0.5 -0.5 -0.5">
            <inertial pos="-0.00565224 0.0434718 0.001476597" quat="0.50045 0.499561 -0.500384 0.499604" mass="0.0152543" diaginertia="5.40253e-06 2.76929e-06 2.76059e-06" />
            <joint name="joint_5" pos="0.0 0.0 0.0" axis="0 0 -1" type="slide" limited="true" range="0.0 0.0012" />
            <geom pos="-0.16256459999999998 0.06872099999999999 -0.1367352" type="mesh" group="0" mesh="original-17" />
            <geom pos="-0.16256459999999998 0.06872099999999999 -0.1367352" type="mesh" group="0" mesh="original-33" />
        </body>
        <body name="link_6" pos="-0.1367352 -0.16256459999999998 -0.06872099999999999" quat="0.5 0.5 -0.5 -0.5">
            <inertial pos="-0.027066990000000003 0.043500899999999995 0.001475286" quat="0.538897 0.4578 -0.539781 0.456777" mass="0.0152383" diaginertia="5.41307e-06 2.78393e-06 2.75593e-06" />
            <joint name="joint_6" pos="0.0 0.0 0.0" axis="0 0 -1" type="slide" limited="true" range="0.0 0.0012" />
            <geom pos="-0.16256459999999998 0.06872099999999999 -0.1367352" type="mesh" group="0" mesh="original-32" />
            <geom pos="-0.16256459999999998 0.06872099999999999 -0.1367352" type="mesh" group="0" mesh="original-16" />
        </body>
        <body name="link_7" pos="-0.1367352 -0.16256459999999998 -0.06872099999999999" quat="0.5 0.5 -0.5 -0.5">
            <inertial pos="0.01576062 0.06345719999999999 0.0014763629999999999" quat="0.498386 0.501707 -0.498157 0.501738" mass="0.0152511" diaginertia="5.40133e-06 2.76679e-06 2.76181e-06" />
            <joint name="joint_7" pos="0.0 0.0 0.0" axis="0 0 -1" type="slide" limited="true" range="0.0 0.0012" />
            <geom pos="-0.16256459999999998 0.06872099999999999 -0.1367352" type="mesh" group="0" mesh="original-15" />
            <geom pos="-0.16256459999999998 0.06872099999999999 -0.1367352" type="mesh" group="0" mesh="original-30" />
        </body>
        <body name="link_8" pos="-0.1367352 -0.16256459999999998 -0.06872099999999999" quat="0.5 0.5 -0.5 -0.5">
            <inertial pos="-0.005642039999999999 0.0634521 0.001476567" quat="0.460979 0.535865 -0.460969 0.536521" mass="0.0152547" diaginertia="5.40482e-06 2.77216e-06 2.75997e-06" />
            <joint name="joint_8" pos="0.0 0.0 0.0" axis="0 0 -1" type="slide" limited="true" range="0.0 0.0012" />
            <geom pos="-0.16256459999999998 0.06872099999999999 -0.1367352" type="mesh" group="0" mesh="original-14" />
            <geom pos="-0.16256459999999998 0.06872099999999999 -0.1367352" type="mesh" group="0" mesh="original-29" />
        </body>
        <body name="link_9" pos="-0.1367352 -0.16256459999999998 -0.06872099999999999" quat="0.5 0.5 -0.5 -0.5">
            <inertial pos="-0.02705958 0.0634584 0.001470678" quat="0.493278 0.506366 -0.493456 0.506726" mass="0.0151735" diaginertia="5.39223e-06 2.76187e-06 2.75547e-06" />
            <joint name="joint_9" pos="0.0 0.0 0.0" axis="0 0 -1" type="slide" limited="true" range="0.0 0.0012" />
            <geom pos="-0.16256459999999998 0.06872099999999999 -0.1367352" type="mesh" group="0" mesh="original-40" />
            <geom pos="-0.16256459999999998 0.06872099999999999 -0.1367352" type="mesh" group="0" mesh="original-13" />
        </body>
        <body name="link_10" pos="-0.1367352 -0.16256459999999998 -0.06872099999999999" quat="0.5 0.5 -0.5 -0.5">
            <inertial pos="0.01577286 0.083445 0.001477026" quat="0.476989 0.52168 -0.477166 0.522153" mass="0.0152608" diaginertia="5.40687e-06 2.77474e-06 2.75963e-06" />
            <joint name="joint_10" pos="0.0 0.0 0.0" axis="0 0 -1" type="slide" limited="true" range="0.0 0.0012" />
            <geom pos="-0.16256459999999998 0.06872099999999999 -0.1367352" type="mesh" group="0" mesh="original-39" />
            <geom pos="-0.16256459999999998 0.06872099999999999 -0.1367352" type="mesh" group="0" mesh="original-22" />
        </body>
        <body name="link_11" pos="-0.1367352 -0.16256459999999998 -0.06872099999999999" quat="0.5 0.5 -0.5 -0.5">
            <inertial pos="-0.0056418 0.0834357 0.001481073" quat="0.515069 0.484096 -0.515002 0.4849" mass="0.015318" diaginertia="5.42126e-06 2.78827e-06 2.76198e-06" />
            <joint name="joint_11" pos="0.0 0.0 0.0" axis="0 0 -1" type="slide" limited="true" range="0.0 0.0012" />
            <geom pos="-0.16256459999999998 0.06872099999999999 -0.1367352" type="mesh" group="0" mesh="original-20" />
            <geom pos="-0.16256459999999998 0.06872099999999999 -0.1367352" type="mesh" group="0" mesh="original-38" />
        </body>
        <body name="link_12" pos="-0.1367352 -0.16256459999999998 -0.06872099999999999" quat="0.5 0.5 -0.5 -0.5">
            <inertial pos="-0.02707638 0.08345910000000001 0.001464678" quat="0.424816 0.565551 -0.424962 0.56488" mass="0.0150911" diaginertia="5.3894e-06 2.76162e-06 2.75066e-06" />
            <joint name="joint_12" pos="0.0 0.0 0.0" axis="0 0 -1" type="slide" limited="true" range="0.0 0.0012" />
            <geom pos="-0.16256459999999998 0.06872099999999999 -0.1367352" type="mesh" group="0" mesh="original-23" />
            <geom pos="-0.16256459999999998 0.06872099999999999 -0.1367352" type="mesh" group="0" mesh="original-37" />
        </body>
        <body name="link_13" pos="-0.1367352 -0.16256459999999998 -0.06872099999999999" quat="0.5 0.5 -0.5 -0.5">
            <inertial pos="0.01576344 0.1034364 0.0014538090000000001" quat="1.15734e-06 0.707107 1.15734e-06 0.707107" mass="0.0149451" diaginertia="5.37555e-06 2.74744e-06 2.74693e-06" />
            <joint name="joint_13" pos="0.0 0.0 0.0" axis="0 0 -1" type="slide" limited="true" range="0.0 0.0012" />
            <geom pos="-0.16256459999999998 0.06872099999999999 -0.1367352" type="mesh" group="0" mesh="original-48" />
            <geom pos="-0.16256459999999998 0.06872099999999999 -0.1367352" type="mesh" group="0" mesh="original-21" />
        </body>
        <body name="link_14" pos="-0.1367352 -0.16256459999999998 -0.06872099999999999" quat="0.5 0.5 -0.5 -0.5">
            <inertial pos="-0.0057119399999999996 0.10342829999999999 0.001485846" quat="-0.0488533 0.706881 0.0490433 0.703937" mass="0.0153893" diaginertia="5.4433e-06 2.79118e-06 2.78271e-06" />
            <joint name="joint_14" pos="0.0 0.0 0.0" axis="0 0 -1" type="slide" limited="true" range="0.0 0.0012" />
            <geom pos="-0.16256459999999998 0.06872099999999999 -0.1367352" type="mesh" group="0" mesh="original-46" />
            <geom pos="-0.16256459999999998 0.06872099999999999 -0.1367352" type="mesh" group="0" mesh="original-27" />
        </body>
        <body name="link_15" pos="-0.1367352 -0.16256459999999998 -0.06872099999999999" quat="0.5 0.5 -0.5 -0.5">
            <inertial pos="-0.027059069999999998 0.10350929999999998 0.001481121" quat="0.526718 0.471473 -0.529363 0.469101" mass="0.0153223" diaginertia="5.447e-06 2.81288e-06 2.76291e-06" />
            <joint name="joint_15" pos="0.0 0.0 0.0" axis="0 0 -1" type="slide" limited="true" range="0.0 0.0012" />
            <geom pos="-0.16256459999999998 0.06872099999999999 -0.1367352" type="mesh" group="0" mesh="original-28" />
            <geom pos="-0.16256459999999998 0.06872099999999999 -0.1367352" type="mesh" group="0" mesh="original-45" />
        </body>
        <body name="link_16" pos="-0.1367352 -0.16256459999999998 -0.06872099999999999" quat="0.5 0.5 -0.5 -0.5">
            <inertial pos="0.01576431 0.12343319999999999 0.001462365" quat="0.521185 0.477846 -0.521504 0.47756" mass="0.0150669" diaginertia="5.38168e-06 2.7526e-06 2.75092e-06" />
            <joint name="joint_16" pos="0.0 0.0 0.0" axis="0 0 -1" type="slide" limited="true" range="0.0 0.0012" />
            <geom pos="-0.16256459999999998 0.06872099999999999 -0.1367352" type="mesh" group="0" mesh="original-47" />
            <geom pos="-0.16256459999999998 0.06872099999999999 -0.1367352" type="mesh" group="0" mesh="original-25" />
        </body>
        <body name="link_17" pos="-0.1367352 -0.16256459999999998 -0.06872099999999999" quat="0.5 0.5 -0.5 -0.5">
            <inertial pos="-0.00561699 0.1234197 0.0014857470000000002" quat="0.00340111 0.706275 -0.00319812 0.707922" mass="0.0154076" diaginertia="5.43481e-06 2.78378e-06 2.78115e-06" />
            <joint name="joint_17" pos="0.0 0.0 0.0" axis="0 0 -1" type="slide" limited="true" range="0.0 0.0012" />
            <geom pos="-0.16256459999999998 0.06872099999999999 -0.1367352" type="mesh" group="0" mesh="original-44" />
            <geom pos="-0.16256459999999998 0.06872099999999999 -0.1367352" type="mesh" group="0" mesh="original-24" />
        </body>
        <body name="link_18" pos="-0.1367352 -0.16256459999999998 -0.06872099999999999" quat="0.5 0.5 -0.5 -0.5">
            <inertial pos="-0.02709618 0.1234236 0.0014861789999999998" quat="-0.00870997 0.707735 0.00871353 0.706371" mass="0.0154121" diaginertia="5.43422e-06 2.78341e-06 2.78114e-06" />
            <joint name="joint_18" pos="0.0 0.0 0.0" axis="0 0 -1" type="slide" limited="true" range="0.0 0.0012" />
            <geom pos="-0.16256459999999998 0.06872099999999999 -0.1367352" type="mesh" group="0" mesh="original-43" />
            <geom pos="-0.16256459999999998 0.06872099999999999 -0.1367352" type="mesh" group="0" mesh="original-26" />
        </body>
        <body name="link_19" pos="0.015551849999999999 0.0334461 0.0" quat="0.5 0.5 -0.5 -0.5">
            <inertial pos="-1.7087429999999998e-08 -0.0667362 -9.07341e-10" quat="0.707107 0 0 0.707107" mass="8.33956" diaginertia="0.417774 0.209422 0.209422" />
            <joint name="joint_19" pos="0.0 0.0 0.0" axis="0 1 0" />
            <geom pos="0.0334461 0.0 0.015551849999999999" type="mesh" group="0" mesh="original-10" />
        </body>
    </body>
        <site name="bottom_site" pos="0 0 -0.3" rgba="0 0 0 0" size="0.005" />
        <site name="top_site" pos="0 0 0.3" rgba="0 0 0 0" size="0.005" />
        <site name="horizontal_radius_site" pos="0.3 0 0" rgba="0 0 0 0" size="0.1" />
    </body>
    </worldbody>
</mujoco>