<mujoco model="partnet_891f65c773939191c834958aed613724">
    <compiler angle="radian" />
    <size njmax="500" nconmax="100" />
    <asset>
        <mesh name="new-6" file="new-6.stl" />
        <mesh name="new-5" file="new-5.stl" />
        <mesh name="original-3" file="original-3.stl" />
        <mesh name="original-4" file="original-4.stl" />
        <mesh name="original-41" file="original-41.stl" />
        <mesh name="original-36" file="original-36.stl" />
        <mesh name="original-35" file="original-35.stl" />
        <mesh name="original-19" file="original-19.stl" />
        <mesh name="original-42" file="original-42.stl" />
        <mesh name="original-34" file="original-34.stl" />
        <mesh name="original-31" file="original-31.stl" />
        <mesh name="original-18" file="original-18.stl" />
        <mesh name="original-17" file="original-17.stl" />
        <mesh name="original-33" file="original-33.stl" />
        <mesh name="original-32" file="original-32.stl" />
        <mesh name="original-16" file="original-16.stl" />
        <mesh name="original-15" file="original-15.stl" />
        <mesh name="original-30" file="original-30.stl" />
        <mesh name="original-14" file="original-14.stl" />
        <mesh name="original-29" file="original-29.stl" />
        <mesh name="original-40" file="original-40.stl" />
        <mesh name="original-13" file="original-13.stl" />
        <mesh name="original-39" file="original-39.stl" />
        <mesh name="original-22" file="original-22.stl" />
        <mesh name="original-20" file="original-20.stl" />
        <mesh name="original-38" file="original-38.stl" />
        <mesh name="original-23" file="original-23.stl" />
        <mesh name="original-37" file="original-37.stl" />
        <mesh name="original-48" file="original-48.stl" />
        <mesh name="original-21" file="original-21.stl" />
        <mesh name="original-46" file="original-46.stl" />
        <mesh name="original-27" file="original-27.stl" />
        <mesh name="original-28" file="original-28.stl" />
        <mesh name="original-45" file="original-45.stl" />
        <mesh name="original-47" file="original-47.stl" />
        <mesh name="original-25" file="original-25.stl" />
        <mesh name="original-44" file="original-44.stl" />
        <mesh name="original-24" file="original-24.stl" />
        <mesh name="original-43" file="original-43.stl" />
        <mesh name="original-26" file="original-26.stl" />
        <mesh name="original-10" file="original-10.stl" />
        <mesh name="original-12" file="original-12.stl" />
        <mesh name="new-4" file="new-4.stl" />
        <mesh name="original-49" file="original-49.stl" />
        <mesh name="original-51" file="original-51.stl" />
        <mesh name="original-1" file="original-1.stl" />
        <mesh name="original-50" file="original-50.stl" />
        <mesh name="new-3" file="new-3.stl" />
        <mesh name="new-2" file="new-2.stl" />
        <mesh name="new-1" file="new-1.stl" />
        <mesh name="new-0" file="new-0.stl" />
    </asset>
    <worldbody>
    <body>
        <body name="object">
        <geom quat="0.5 0.5 -0.5 -0.5" type="mesh" group="0" mesh="original-12" conaffinity="0" contype="0"/>
        <geom quat="0.5 0.5 -0.5 -0.5" type="mesh" group="0" mesh="new-4" conaffinity="0" contype="0" />
        <geom quat="0.5 0.5 -0.5 -0.5" type="mesh" group="0" mesh="original-49" conaffinity="0" contype="0"/>
        <geom quat="0.5 0.5 -0.5 -0.5" type="mesh" group="0" mesh="original-51" conaffinity="0" contype="0"/>
        <geom quat="0.5 0.5 -0.5 -0.5" type="mesh" group="0" mesh="original-1" conaffinity="0" contype="0"/>
        <geom quat="0.5 0.5 -0.5 -0.5" type="mesh" group="0" mesh="original-50" conaffinity="0" contype="0"/>
        <geom quat="0.5 0.5 -0.5 -0.5" type="mesh" group="0" mesh="new-3" conaffinity="0" contype="0"/>
        <geom quat="0.5 0.5 -0.5 -0.5" type="mesh" group="0" mesh="new-2" conaffinity="0" contype="0"/>
        <geom quat="0.5 0.5 -0.5 -0.5" type="mesh" group="0" mesh="new-1" conaffinity="0" contype="0"/>
        <geom quat="0.5 0.5 -0.5 -0.5" type="mesh" group="0" mesh="new-0" conaffinity="0" contype="0"/>
        <body name="link_0" pos="-0.359218 0.618785 0" quat="0.5 0.5 -0.5 -0.5">
            <inertial pos="0.414829 0.0166444 0.298924" quat="0.00349468 0.499467 -0.00703786 0.866297" mass="72.4061" diaginertia="9.0744 5.85664 3.30306" />
            <joint name="joint_0" pos="0 0 0" axis="0 -1 0" limited="true" range="-0.523599 1.39626" />
            <!-- <site name="hinge_site" pos="0 0 0" rgba="0 0 0 0" size="0.005" /> -->
            <geom name="panel" pos="0.618785 0 -0.359218" type="mesh" group="0" mesh="new-6" />
            <geom pos="0.618785 0 -0.359218" type="mesh" group="0" mesh="new-5" />
            <geom pos="0.618785 0 -0.359218" type="mesh" group="0" mesh="original-3" />
            <geom pos="0.618785 0 -0.359218" type="mesh" group="0" mesh="original-4" />
        </body>
        <body name="link_1" pos="-0.455784 -0.541882 -0.22907" quat="0.5 0.5 -0.5 -0.5">
            <inertial pos="0.0525268 0.0782934 0.00494252" quat="0.416789 0.571373 -0.416729 0.571101" mass="0.0153622" diaginertia="5.42181e-06 2.78238e-06 2.76854e-06" />
            <joint name="joint_1" pos="0 0 0" axis="0 0 -1" type="slide" limited="true" range="0 0.004" />
            <geom pos="-0.541882 0.22907 -0.455784" type="mesh" group="0" mesh="original-41" />
            <geom pos="-0.541882 0.22907 -0.455784" type="mesh" group="0" mesh="original-36" />
        </body>
        <body name="link_2" pos="-0.455784 -0.541882 -0.22907" quat="0.5 0.5 -0.5 -0.5">
            <inertial pos="-0.0188435 0.0782797 0.00492333" quat="0.523586 0.475286 -0.523487 0.475312" mass="0.0152598" diaginertia="5.40253e-06 2.76766e-06 2.76238e-06" />
            <joint name="joint_2" pos="0 0 0" axis="0 0 -1" type="slide" limited="true" range="0 0.004" />
            <geom pos="-0.541882 0.22907 -0.455784" type="mesh" group="0" mesh="original-35" />
            <geom pos="-0.541882 0.22907 -0.455784" type="mesh" group="0" mesh="original-19" />
        </body>
        <body name="link_3" pos="-0.455784 -0.541882 -0.22907" quat="0.5 0.5 -0.5 -0.5">
            <inertial pos="-0.0902985 0.0782677 0.00495284" quat="0.511133 0.489369 -0.510207 0.488824" mass="0.0154119" diaginertia="5.43794e-06 2.79688e-06 2.77117e-06" />
            <joint name="joint_3" pos="0 0 0" axis="0 0 -1" type="slide" limited="true" range="0 0.004" />
            <geom pos="-0.541882 0.22907 -0.455784" type="mesh" group="0" mesh="original-42" />
            <geom pos="-0.541882 0.22907 -0.455784" type="mesh" group="0" mesh="original-34" />
        </body>
        <body name="link_4" pos="-0.455784 -0.541882 -0.22907" quat="0.5 0.5 -0.5 -0.5">
            <inertial pos="0.0525505 0.144933 0.00491951" quat="0.433322 0.558723 -0.433633 0.55859" mass="0.015244" diaginertia="5.40095e-06 2.76746e-06 2.76057e-06" />
            <joint name="joint_4" pos="0 0 0" axis="0 0 -1" type="slide" limited="true" range="0 0.004" />
            <geom pos="-0.541882 0.22907 -0.455784" type="mesh" group="0" mesh="original-31" />
            <geom pos="-0.541882 0.22907 -0.455784" type="mesh" group="0" mesh="original-18" />
        </body>
        <body name="link_5" pos="-0.455784 -0.541882 -0.22907" quat="0.5 0.5 -0.5 -0.5">
            <inertial pos="-0.0188408 0.144906 0.00492199" quat="0.50045 0.499561 -0.500384 0.499604" mass="0.0152543" diaginertia="5.40253e-06 2.76929e-06 2.76059e-06" />
            <joint name="joint_5" pos="0 0 0" axis="0 0 -1" type="slide" limited="true" range="0 0.004" />
            <geom pos="-0.541882 0.22907 -0.455784" type="mesh" group="0" mesh="original-17" />
            <geom pos="-0.541882 0.22907 -0.455784" type="mesh" group="0" mesh="original-33" />
        </body>
        <body name="link_6" pos="-0.455784 -0.541882 -0.22907" quat="0.5 0.5 -0.5 -0.5">
            <inertial pos="-0.0902233 0.145003 0.00491762" quat="0.538897 0.4578 -0.539781 0.456777" mass="0.0152383" diaginertia="5.41307e-06 2.78393e-06 2.75593e-06" />
            <joint name="joint_6" pos="0 0 0" axis="0 0 -1" type="slide" limited="true" range="0 0.004" />
            <geom pos="-0.541882 0.22907 -0.455784" type="mesh" group="0" mesh="original-32" />
            <geom pos="-0.541882 0.22907 -0.455784" type="mesh" group="0" mesh="original-16" />
        </body>
        <body name="link_7" pos="-0.455784 -0.541882 -0.22907" quat="0.5 0.5 -0.5 -0.5">
            <inertial pos="0.0525354 0.211524 0.00492121" quat="0.498386 0.501707 -0.498157 0.501738" mass="0.0152511" diaginertia="5.40133e-06 2.76679e-06 2.76181e-06" />
            <joint name="joint_7" pos="0 0 0" axis="0 0 -1" type="slide" limited="true" range="0 0.004" />
            <geom pos="-0.541882 0.22907 -0.455784" type="mesh" group="0" mesh="original-15" />
            <geom pos="-0.541882 0.22907 -0.455784" type="mesh" group="0" mesh="original-30" />
        </body>
        <body name="link_8" pos="-0.455784 -0.541882 -0.22907" quat="0.5 0.5 -0.5 -0.5">
            <inertial pos="-0.0188068 0.211507 0.00492189" quat="0.460979 0.535865 -0.460969 0.536521" mass="0.0152547" diaginertia="5.40482e-06 2.77216e-06 2.75997e-06" />
            <joint name="joint_8" pos="0 0 0" axis="0 0 -1" type="slide" limited="true" range="0 0.004" />
            <geom pos="-0.541882 0.22907 -0.455784" type="mesh" group="0" mesh="original-14" />
            <geom pos="-0.541882 0.22907 -0.455784" type="mesh" group="0" mesh="original-29" />
        </body>
        <body name="link_9" pos="-0.455784 -0.541882 -0.22907" quat="0.5 0.5 -0.5 -0.5">
            <inertial pos="-0.0901986 0.211528 0.00490226" quat="0.493278 0.506366 -0.493456 0.506726" mass="0.0151735" diaginertia="5.39223e-06 2.76187e-06 2.75547e-06" />
            <joint name="joint_9" pos="0 0 0" axis="0 0 -1" type="slide" limited="true" range="0 0.004" />
            <geom pos="-0.541882 0.22907 -0.455784" type="mesh" group="0" mesh="original-40" />
            <geom pos="-0.541882 0.22907 -0.455784" type="mesh" group="0" mesh="original-13" />
        </body>
        <body name="link_10" pos="-0.455784 -0.541882 -0.22907" quat="0.5 0.5 -0.5 -0.5">
            <inertial pos="0.0525762 0.27815 0.00492342" quat="0.476989 0.52168 -0.477166 0.522153" mass="0.0152608" diaginertia="5.40687e-06 2.77474e-06 2.75963e-06" />
            <joint name="joint_10" pos="0 0 0" axis="0 0 -1" type="slide" limited="true" range="0 0.004" />
            <geom pos="-0.541882 0.22907 -0.455784" type="mesh" group="0" mesh="original-39" />
            <geom pos="-0.541882 0.22907 -0.455784" type="mesh" group="0" mesh="original-22" />
        </body>
        <body name="link_11" pos="-0.455784 -0.541882 -0.22907" quat="0.5 0.5 -0.5 -0.5">
            <inertial pos="-0.018806 0.278119 0.00493691" quat="0.515069 0.484096 -0.515002 0.4849" mass="0.015318" diaginertia="5.42126e-06 2.78827e-06 2.76198e-06" />
            <joint name="joint_11" pos="0 0 0" axis="0 0 -1" type="slide" limited="true" range="0 0.004" />
            <geom pos="-0.541882 0.22907 -0.455784" type="mesh" group="0" mesh="original-20" />
            <geom pos="-0.541882 0.22907 -0.455784" type="mesh" group="0" mesh="original-38" />
        </body>
        <body name="link_12" pos="-0.455784 -0.541882 -0.22907" quat="0.5 0.5 -0.5 -0.5">
            <inertial pos="-0.0902546 0.278197 0.00488226" quat="0.424816 0.565551 -0.424962 0.56488" mass="0.0150911" diaginertia="5.3894e-06 2.76162e-06 2.75066e-06" />
            <joint name="joint_12" pos="0 0 0" axis="0 0 -1" type="slide" limited="true" range="0 0.004" />
            <geom pos="-0.541882 0.22907 -0.455784" type="mesh" group="0" mesh="original-23" />
            <geom pos="-0.541882 0.22907 -0.455784" type="mesh" group="0" mesh="original-37" />
        </body>
        <body name="link_13" pos="-0.455784 -0.541882 -0.22907" quat="0.5 0.5 -0.5 -0.5">
            <inertial pos="0.0525448 0.344788 0.00484603" quat="1.15734e-06 0.707107 1.15734e-06 0.707107" mass="0.0149451" diaginertia="5.37555e-06 2.74744e-06 2.74693e-06" />
            <joint name="joint_13" pos="0 0 0" axis="0 0 -1" type="slide" limited="true" range="0 0.004" />
            <geom pos="-0.541882 0.22907 -0.455784" type="mesh" group="0" mesh="original-48" />
            <geom pos="-0.541882 0.22907 -0.455784" type="mesh" group="0" mesh="original-21" />
        </body>
        <body name="link_14" pos="-0.455784 -0.541882 -0.22907" quat="0.5 0.5 -0.5 -0.5">
            <inertial pos="-0.0190398 0.344761 0.00495282" quat="-0.0488533 0.706881 0.0490433 0.703937" mass="0.0153893" diaginertia="5.4433e-06 2.79118e-06 2.78271e-06" />
            <joint name="joint_14" pos="0 0 0" axis="0 0 -1" type="slide" limited="true" range="0 0.004" />
            <geom pos="-0.541882 0.22907 -0.455784" type="mesh" group="0" mesh="original-46" />
            <geom pos="-0.541882 0.22907 -0.455784" type="mesh" group="0" mesh="original-27" />
        </body>
        <body name="link_15" pos="-0.455784 -0.541882 -0.22907" quat="0.5 0.5 -0.5 -0.5">
            <inertial pos="-0.0901969 0.345031 0.00493707" quat="0.526718 0.471473 -0.529363 0.469101" mass="0.0153223" diaginertia="5.447e-06 2.81288e-06 2.76291e-06" />
            <joint name="joint_15" pos="0 0 0" axis="0 0 -1" type="slide" limited="true" range="0 0.004" />
            <geom pos="-0.541882 0.22907 -0.455784" type="mesh" group="0" mesh="original-28" />
            <geom pos="-0.541882 0.22907 -0.455784" type="mesh" group="0" mesh="original-45" />
        </body>
        <body name="link_16" pos="-0.455784 -0.541882 -0.22907" quat="0.5 0.5 -0.5 -0.5">
            <inertial pos="0.0525477 0.411444 0.00487455" quat="0.521185 0.477846 -0.521504 0.47756" mass="0.0150669" diaginertia="5.38168e-06 2.7526e-06 2.75092e-06" />
            <joint name="joint_16" pos="0 0 0" axis="0 0 -1" type="slide" limited="true" range="0 0.004" />
            <geom pos="-0.541882 0.22907 -0.455784" type="mesh" group="0" mesh="original-47" />
            <geom pos="-0.541882 0.22907 -0.455784" type="mesh" group="0" mesh="original-25" />
        </body>
        <body name="link_17" pos="-0.455784 -0.541882 -0.22907" quat="0.5 0.5 -0.5 -0.5">
            <inertial pos="-0.0187233 0.411399 0.00495249" quat="0.00340111 0.706275 -0.00319812 0.707922" mass="0.0154076" diaginertia="5.43481e-06 2.78378e-06 2.78115e-06" />
            <joint name="joint_17" pos="0 0 0" axis="0 0 -1" type="slide" limited="true" range="0 0.004" />
            <geom pos="-0.541882 0.22907 -0.455784" type="mesh" group="0" mesh="original-44" />
            <geom pos="-0.541882 0.22907 -0.455784" type="mesh" group="0" mesh="original-24" />
        </body>
        <body name="link_18" pos="-0.455784 -0.541882 -0.22907" quat="0.5 0.5 -0.5 -0.5">
            <inertial pos="-0.0903206 0.411412 0.00495393" quat="-0.00870997 0.707735 0.00871353 0.706371" mass="0.0154121" diaginertia="5.43422e-06 2.78341e-06 2.78114e-06" />
            <joint name="joint_18" pos="0 0 0" axis="0 0 -1" type="slide" limited="true" range="0 0.004" />
            <geom pos="-0.541882 0.22907 -0.455784" type="mesh" group="0" mesh="original-43" />
            <geom pos="-0.541882 0.22907 -0.455784" type="mesh" group="0" mesh="original-26" />
        </body>
        <body name="link_19" pos="0.0518395 0.111487 0" quat="0.5 0.5 -0.5 -0.5">
            <inertial pos="-5.69581e-08 -0.222454 -3.02447e-09" quat="0.707107 0 0 0.707107" mass="8.33956" diaginertia="0.417774 0.209422 0.209422" />
            <joint name="joint_19" pos="0 0 0" axis="0 1 0" />
            <geom pos="0.111487 0 0.0518395" type="mesh" group="0" mesh="original-10" />
        </body>
    </body>
        <site name="bottom_site" pos="0 0 -0.3" rgba="0 0 0 0" size="0.005"/>
        <site name="top_site" pos="0 0 0.3" rgba="0 0 0 0" size="0.005"/>
        <site name="horizontal_radius_site" pos="0.3 0 0" rgba="0 0 0 0" size="0.1"/>
    </body>
    </worldbody>
</mujoco>
