<mujoco model="partnet_785d6d568e0c7ea5575f4e5007488531">
    <compiler angle="radian" />
    <option gravity="0 0 0"/>
    <size njmax="500" nconmax="100" />
    <asset>
        <mesh name="new-5" file="new-5.stl" />
        <mesh name="new-8" file="new-8.stl" />
        <mesh name="new-4" file="new-4.stl" />
        <mesh name="new-3" file="new-3.stl" />
        <mesh name="new-2" file="new-2.stl" />
        <mesh name="new-1" file="new-1.stl" />
        <mesh name="new-0" file="new-0.stl" />
        <mesh name="new-7" file="new-7.stl" />
    </asset>
    <worldbody>
    <body>
        <body name="object" >
        <geom quat="0.5 0.5 -0.5 -0.5" type="mesh" group="0" mesh="new-8" />
        <geom quat="0.5 0.5 -0.5 -0.5" type="mesh" group="0" mesh="new-4" />
        <geom quat="0.5 0.5 -0.5 -0.5" type="mesh" group="0" mesh="new-3" />
        <geom quat="0.5 0.5 -0.5 -0.5" type="mesh" group="0" mesh="new-2" />
        <geom quat="0.5 0.5 -0.5 -0.5" type="mesh" group="0" mesh="new-1" />
        <geom quat="0.5 0.5 -0.5 -0.5" type="mesh" group="0" mesh="new-0" />
        <geom quat="0.5 0.5 -0.5 -0.5" type="mesh" group="0" mesh="new-7" />
        <body name="link_0" pos="-0.437532 -0.407398 -0.445902" quat="0.5 0.5 -0.5 -0.5" gravcomp="1">
            <inertial pos="-0.4101 0.554497 0.0555271" quat="0.497242 0.502516 -0.501348 0.498877" mass="68.7029" diaginertia="11.5805 7.63474 4.00435" />
            <joint name="joint_0" pos="0 0 0" axis="1 0 0" limited="true" range="0 1.5708" />
            <geom pos="-0.407398 0.445902 -0.437532" type="mesh" group="0" mesh="new-5" />
        </body>
    </body>
        <site name="bottom_site" pos="0 0 -0.3" rgba="0 0 0 0" size="0.005"/>
        <site name="top_site" pos="0 0 0.3" rgba="0 0 0 0" size="0.005"/>
        <site name="horizontal_radius_site" pos="0.3 0 0" rgba="0 0 0 0" size="0.1"/>
    </body>
    </worldbody>
</mujoco>
