<?xml version="1.0" ?>
<robot name="partnet_785d6d568e0c7ea5575f4e5007488531">
	<link name="base"/>
	<link name="link_0">
		<visual name="door_frame-11">
			<origin xyz="-0.4073980000000006 0.4459024187863928 -0.4375324648179948"/>
			<geometry>
				<mesh filename="textured_objs/new-5.stl"/>
			</geometry>
		</visual>
		<collision>
			<origin xyz="-0.4073980000000006 0.4459024187863928 -0.4375324648179948"/>
			<geometry>
				<mesh filename="textured_objs/new-5.stl"/>
			</geometry>
		</collision>
	</link>
	<joint name="joint_0" type="revolute">
		<origin xyz="0.4073980000000006 -0.4459024187863928 0.4375324648179948"/>
		<axis xyz="1 0 0"/>
		<child link="link_0"/>
		<parent link="link_1"/>
		<limit lower="0.0" upper="1.5707963267948966"/>
	</joint>
	<link name="link_1">
		<visual name="frame-9">
			<origin xyz="0 0 0"/>
			<geometry>
				<mesh filename="textured_objs/new-8.stl"/>
			</geometry>
		</visual>
		<visual name="foot-4">
			<origin xyz="0 0 0"/>
			<geometry>
				<mesh filename="textured_objs/new-4.stl"/>
			</geometry>
		</visual>
		<visual name="foot-5">
			<origin xyz="0 0 0"/>
			<geometry>
				<mesh filename="textured_objs/new-3.stl"/>
			</geometry>
		</visual>
		<visual name="foot-6">
			<origin xyz="0 0 0"/>
			<geometry>
				<mesh filename="textured_objs/new-2.stl"/>
			</geometry>
		</visual>
		<visual name="foot-7">
			<origin xyz="0 0 0"/>
			<geometry>
				<mesh filename="textured_objs/new-1.stl"/>
			</geometry>
		</visual>
		<visual name="surface-8">
			<origin xyz="0 0 0"/>
			<geometry>
				<mesh filename="textured_objs/new-0.stl"/>
			</geometry>
		</visual>
		<visual name="surface-8">
			<origin xyz="0 0 0"/>
			<geometry>
				<mesh filename="textured_objs/new-7.stl"/>
			</geometry>
		</visual>
		<collision>
			<origin xyz="0 0 0"/>
			<geometry>
				<mesh filename="textured_objs/new-8.stl"/>
			</geometry>
		</collision>
		<collision>
			<origin xyz="0 0 0"/>
			<geometry>
				<mesh filename="textured_objs/new-4.stl"/>
			</geometry>
		</collision>
		<collision>
			<origin xyz="0 0 0"/>
			<geometry>
				<mesh filename="textured_objs/new-3.stl"/>
			</geometry>
		</collision>
		<collision>
			<origin xyz="0 0 0"/>
			<geometry>
				<mesh filename="textured_objs/new-2.stl"/>
			</geometry>
		</collision>
		<collision>
			<origin xyz="0 0 0"/>
			<geometry>
				<mesh filename="textured_objs/new-1.stl"/>
			</geometry>
		</collision>
		<collision>
			<origin xyz="0 0 0"/>
			<geometry>
				<mesh filename="textured_objs/new-0.stl"/>
			</geometry>
		</collision>
		<collision>
			<origin xyz="0 0 0"/>
			<geometry>
				<mesh filename="textured_objs/new-7.stl"/>
			</geometry>
		</collision>
	</link>
	<joint name="joint_1" type="fixed">
		<origin rpy="1.570796326794897 0 -1.570796326794897" xyz="0 0 0"/>
		<child link="link_1"/>
		<parent link="base"/>
	</joint>
</robot>
