<?xml version="1.0" ?>
<robot name="partnet_e19887ca50862a434c86b1fdc94892eb">
	<link name="base"/>
	<link name="link_0">
		<visual name="container_box-9">
			<origin xyz="0 0 0"/>
			<geometry>
				<mesh filename="textured_objs/new-7.stl"/>
			</geometry>
		</visual>
		<visual name="container_box-9">
			<origin xyz="0 0 0"/>
			<geometry>
				<mesh filename="textured_objs/new-6.stl"/>
			</geometry>
		</visual>
		<visual name="container_box-10">
			<origin xyz="0 0 0"/>
			<geometry>
				<mesh filename="textured_objs/new-9.stl"/>
			</geometry>
		</visual>
		<visual name="container_box-11">
			<origin xyz="0 0 0"/>
			<geometry>
				<mesh filename="textured_objs/new-8.stl"/>
			</geometry>
		</visual>
		<visual name="container_box-12">
			<origin xyz="0 0 0"/>
			<geometry>
				<mesh filename="textured_objs/new-3.stl"/>
			</geometry>
		</visual>
		<visual name="container_bottom-13">
			<origin xyz="0 0 0"/>
			<geometry>
				<mesh filename="textured_objs/new-4.stl"/>
			</geometry>
		</visual>
		<visual name="container_bottom-13">
			<origin xyz="0 0 0"/>
			<geometry>
				<mesh filename="textured_objs/new-5.stl"/>
			</geometry>
		</visual>
		<collision>
			<origin xyz="0 0 0"/>
			<geometry>
				<mesh filename="textured_objs/new-7.stl"/>
			</geometry>
		</collision>
		<collision>
			<origin xyz="0 0 0"/>
			<geometry>
				<mesh filename="textured_objs/new-6.stl"/>
			</geometry>
		</collision>
		<collision>
			<origin xyz="0 0 0"/>
			<geometry>
				<mesh filename="textured_objs/new-9.stl"/>
			</geometry>
		</collision>
		<collision>
			<origin xyz="0 0 0"/>
			<geometry>
				<mesh filename="textured_objs/new-8.stl"/>
			</geometry>
		</collision>
		<collision>
			<origin xyz="0 0 0"/>
			<geometry>
				<mesh filename="textured_objs/new-3.stl"/>
			</geometry>
		</collision>
		<collision>
			<origin xyz="0 0 0"/>
			<geometry>
				<mesh filename="textured_objs/new-4.stl"/>
			</geometry>
		</collision>
		<collision>
			<origin xyz="0 0 0"/>
			<geometry>
				<mesh filename="textured_objs/new-5.stl"/>
			</geometry>
		</collision>
	</link>
	<joint name="joint_0" type="prismatic">
		<origin xyz="0 0 0"/>
		<axis xyz="0 0 1"/>
		<child link="link_0"/>
		<parent link="link_1"/>
		<limit lower="-0.21199999999999997" upper="0.54"/>
	</joint>
	<link name="link_1">
		<visual name="cover_lid-8">
			<origin xyz="0 0 0"/>
			<geometry>
				<mesh filename="textured_objs/new-1.stl"/>
			</geometry>
		</visual>
		<visual name="frame_holistic-3">
			<origin xyz="0 0 0"/>
			<geometry>
				<mesh filename="textured_objs/new-2.stl"/>
			</geometry>
		</visual>
		<visual name="frame_bottom-4">
			<origin xyz="0 0 0"/>
			<geometry>
				<mesh filename="textured_objs/new-0.stl"/>
			</geometry>
		</visual>
		<collision>
			<origin xyz="0 0 0"/>
			<geometry>
				<mesh filename="textured_objs/new-1.stl"/>
			</geometry>
		</collision>
		<collision>
			<origin xyz="0 0 0"/>
			<geometry>
				<mesh filename="textured_objs/new-2.stl"/>
			</geometry>
		</collision>
		<collision>
			<origin xyz="0 0 0"/>
			<geometry>
				<mesh filename="textured_objs/new-0.stl"/>
			</geometry>
		</collision>
	</link>
	<joint name="joint_1" type="fixed">
		<origin rpy="1.570796326794897 0 -1.570796326794897" xyz="0 0 0"/>
		<child link="link_1"/>
		<parent link="base"/>
	</joint>
</robot>
