<mujoco model="partnet_e19887ca50862a434c86b1fdc94892eb">
    <compiler angle="radian" />
    <size njmax="500" nconmax="100" />
    <asset>
        <mesh name="new-7" file="new-7.stl" />
        <mesh name="new-6" file="new-6.stl" />
        <mesh name="new-9" file="new-9.stl" />
        <mesh name="new-8" file="new-8.stl" />
        <mesh name="new-3" file="new-3.stl" />
        <mesh name="new-4" file="new-4.stl" />
        <mesh name="new-5" file="new-5.stl" />
        <mesh name="new-1" file="new-1.stl" />
        <mesh name="new-2" file="new-2.stl" />
        <mesh name="new-0" file="new-0.stl" />
    </asset>
    <worldbody>
    <body>
        <body name="object">
        <geom quat="0.5 0.5 -0.5 -0.5" type="mesh" group="0" mesh="new-1" conaffinity="0" contype="0"/>
        <geom quat="0.5 0.5 -0.5 -0.5" type="mesh" group="0" mesh="new-2" conaffinity="0" contype="0"/>
        <geom quat="0.5 0.5 -0.5 -0.5" type="mesh" group="0" mesh="new-0" conaffinity="0" contype="0"/>
        <body name="link_0" pos="0 0 0" quat="0.5 0.5 -0.5 -0.5">
            <inertial pos="-0.00671358 0.0601354 0.314128" quat="0.905341 0.422676 -0.00552584 -0.0408932" mass="136.137" diaginertia="29.5371 21.9492 18.6081" />
            <joint name="joint_0" pos="0 0 0" axis="0 0 1" type="slide" limited="true" range="-0.212 0.54" />
            <geom type="mesh" group="0" mesh="new-7" />
            <geom type="mesh" group="0" mesh="new-6" />
            <geom type="mesh" group="0" mesh="new-9" />
            <geom type="mesh" group="0" mesh="new-8" />
            <geom type="mesh" group="0" mesh="new-3" />
            <geom type="mesh" group="0" mesh="new-4" />
            <geom type="mesh" group="0" mesh="new-5" />
        </body>
    </body>
        <site name="bottom_site" pos="0 0 -0.3" rgba="0 0 0 0" size="0.005"/>
        <site name="top_site" pos="0 0 0.3" rgba="0 0 0 0" size="0.005"/>
        <site name="horizontal_radius_site" pos="0.3 0 0" rgba="0 0 0 0" size="0.1"/>
    </body>
    </worldbody>
</mujoco>
